<mujoco model="key">
  <worldbody>
    <body name="key_body" pos="0 0 0">
      <!-- This joint allows the object to tumble -->
      <joint type="hinge" damping="0.01" axis="0 0 1" />
      <!-- <geom name="key_handle_geom1" type="box" fromto="0 0 0 .1 .3 .2" size="0.1 0.3 0.2" density="2"/>
      <geom name="key_handle_geom2" type="box" fromto=".2 0 0 .3 .3 .2" size="0.1 0.3 0.2" density="2"/>
      <geom name="key_handle_geom3" type="box" fromto=".1 .2 0 .2 .7 .2" size="0.1 0.7 0.2" density="2"/>
      <geom name="key_handle_geom4" type="box" fromto="0 .6 .2 .1 .7 .2" size="0.1 0.1 0.2" density="2"/> -->
      <geom name="key_handle_geom1" type="box" pos=".1 .3 .2" size="0.1 0.3 0.2" density="2"/>
      <geom name="key_handle_geom2" type="box" pos=".5 .3 .2" size="0.1 0.3 0.2" density="2"/>
      <geom name="key_handle_geom3" type="box" pos=".3 .9 .2" size="0.1 0.5 0.2" density="2"/>
      <geom name="key_handle_geom4" type="box" pos=".3 .1 .2" size="0.1 0.1 0.2" density="2"/>
      <geom name="key_nib1" type="box" pos=".1 .9 .2" size="0.1 0.1 0.2" density="2"/>
      <geom name="key_nib2" type="box" pos=".1 1.3 .2" size="0.1 0.1 0.2" density="2"/>
    </body>
  </worldbody>
</mujoco>